Workbook
Name ADM_D01: Emp_ADM[Name_AR]
Name ADM_D01: Emp_ADM[Name_AR]
Name ADM_D01: Emp_ADM[Name_AR]
Name All_D11: Emp_All[Name_AR]
Name All_D11: Emp_All[Name_AR]
Name All_D11: Emp_All[Name_AR]
Name CON_D03: Emp_CON[Name_AR]
Name CON_D03: Emp_CON[Name_AR]
Name CON_D03: Emp_CON[Name_AR]
Name DeptList: Lookups!$B$2:$B$11
Name ELE_D04: Emp_ELE[Name_AR]
Name ELE_D04: Emp_ELE[Name_AR]
Name ELE_D04: Emp_ELE[Name_AR]
Name EmpDepts: Master_Employee!$D$5:$D$30
Name EmpIDs: Master_Employee!$B$5:$B$30
Name EmpNames: Master_Employee!$H$5:$H$30
Name EmpStatus: Lookups!$F$2:$F$5
Name FIN_D02: Emp_FIN[Name_AR]
Name FIN_D02: Emp_FIN[Name_AR]
Name FIN_D02: Emp_FIN[Name_AR]
Name PayMethods: Lookups!$D$2:$D$4
Name PLM_D05: Emp_PLM[Name_AR]
Name PLM_D05: Emp_PLM[Name_AR]
Name PLM_D05: Emp_PLM[Name_AR]
Name ProjectList: Projects!$B$4:$B$70
Name ProjectNames: Projects!$C$4:$C$70
Name Slicer_Dept_Name: #N/A
Name Slicer_Emp_Status: #N/A
Name Slicer_Grade: #N/A
Name Slicer_Job_Title: #N/A
Name Slicer_Payment_Method: #N/A
Name Slicer_Project_Name: #N/A
Name Slicer_Supervisor: #N/A
Name STN_D06: Emp_STN[Name_AR]
Name STN_D06: Emp_STN[Name_AR]
Name STN_D06: Emp_STN[Name_AR]
Name SupvList: Master_Employee!$H$5:$H$30
Name Timeline_Month: #N/A
Name TransTypes: Lookups!$H$2:$H$5

Sheet Lookups
A1: Dept_ID | B1: Dept_Name | D1: Payment_Method | F1: Status | H1: Trans_Type
A2: ADM_D01 | B2: الإدارة | D2: كاش - Cash | F2: يعمل - Active | H2: سلف - Advance
A3: FIN_D02 | B3: التشطيبات | D3: بنك - Bank | F3: اجازة - Vacation | H3: خصم - Deduction
A4: CON_D03 | B4: الإنشاءات | D4: فودافون - Vodafone | F4: استقالة - Resigned | H4: بونص - Bonus
A5: ELE_D04 | B5: الكهرباء | F5: اجازة مرضية - Sick Leave | H5: زيادة - Addition
A6: PLM_D05 | B6: السباكة
A7: STN_D06 | B7: الحجر
A8: ALU_D07 | B8: الألمنيوم
A9: EQP_D08 | B9: المعدات
A10: CRP_D09 | B10: النجارة
A11: PTG_D10 | B11: الدهانات

Sheet HR_Dashboard

Sheet Project_Cost_Dashboard 

Sheet Payroll Analysis

Sheet Pivot_Tables
A1: Payroll Analysis
C2: Total Net Salary | F2: AVG Salary | G2: #EMP | AG2: HR Analysis
C3: Net Salary | D3: Max Salary | E3: Min Salary | F3: Avg Salary | G3: Selected Month Salary | H3: Previous Month Salary | I3: Difference Display | J3: Workers Count
C4: 12846.25 | D4: 2300 | E4: 1100 | F4: 1680.7812 | G4: 12846.25 | H4: 5366.25 | I4: ↑ 7,480 | J4: 8 | AI4: Total Employees | AJ4: #Department
C5: =GETPIVOTDATA("[Measures].[Net Salary]",$C$3) -> 12846.25 | D5: =GETPIVOTDATA("[Measures].[Max Salary]",$C$3) -> 2300 | E5: =GETPIVOTDATA("[Measures].[Min Salary]",$C$3) -> 1100 | F5: =GETPIVOTDATA("[Measures].[Avg Salary]",$C$3) -> 1680.7812 | G5: =GETPIVOTDATA("[Measures].[Selected Month Salary]",$C$3) -> 12846.25 | H5: =GETPIVOTDATA("[Measures].[Previous Month Salary]",$C$3) -> 5366.25 | I5: =GETPIVOTDATA("[Measures].[Difference Display]",$C$3) -> ↑ 7,480 | J5: =GETPIVOTDATA("[Measures].[Workers Count]",$C$3) -> 8 | O5: Salary by Dep | AI5: Employee Count | AJ5: Count of Dept_ID | AK5: Count of Project_ID | AL5: Count of Nationality
H6: hاعلى مهنة بتكلفني مرتبات | AG6: =GETPIVOTDATA("[Measures].[Employee Count]",$AI$5) -> 26 | AI6: 26 | AJ6: 14 | AK6: 67 | AL6: 26
D7: Salary by job title and #Job_title | O7: Row Labels | P7: Net Salary | W7: Row Labels | X7: Net Salary | AJ7: =GETPIVOTDATA("[Measures].[Count of Dept_ID 2]",$AJ$5) -> 14 | AK7: =GETPIVOTDATA("[Measures].[Count of Project_ID]",$AK$5) -> 67
A8: Row Labels | B8: Net Salary | G8: Row Labels | H8: Net Salary | O8: الإدارة | W8: (blank) | X8: -750 | AI8: Employee by Grade | AL8: Employees by Job Title | AO8: Employee By Status | AS8: Employee By Department | AV8: Employee By Sponsership | AZ8: Salary by Job Title
A9: Bank - بنك | B9: 4450.8333 | G9: مشرف_موقع | H9: 960.83333 | O9: ADM_D01 | P9: 2780 | W9: 46082 | X9: 5366.25 | AI9: Row Labels | AJ9: Count of Emp_ID | AL9: Row Labels | AM9: Count of Emp_ID | AO9: Row Labels | AP9: Count of Status_Code | AS9: Row Labels | AT9: Count of Emp_ID | AV9: Row Labels | AW9: Count of Emp_ID | AZ9: Row Labels | BA9: Sum of Total_Salary
A10: cash - نقدا | B10: 3900 | G10: عامل | H10: 1100 | O10: الإنشاءات | W10: 46113 | X10: 6730 | AI10: Manager | AJ10: 2 | AL10: فني عزل | AM10: 1 | AO10: New appointment - تعيين جديد | AP10: 1 | AS10: الإدارة | AT10: 6 | AV10: غير كفالة-NoSponsership | AW10: 8 | AZ10: Manager
A11: Vodafone - فودافون | B11: 4495.4167 | G11: مساعد كهربائي | H11: 1233.3333 | O11: CON_D03 | P11: 2795.4167 | W11: Grand Total | X11: 12846.25 | AI11: Supervisor | AJ11: 2 | AL11: سائق | AM11: 1 | AO11: vacation - إجازة | AP11: 3 | AS11: الإنشاءات | AT11: 10 | AV11: كفالة-Sponsership | AW11: 18 | AZ11: مشرف_موقع | BA11: 3200
A12: Grand Total | B12: 12846.25 | G12: صباغ | H12: 1437.5 | O12: التشطيبات | AI12: Worker | AJ12: 22 | AL12: فني بلاستر | AM12: 1 | AO12: works - يعمل | AP12: 22 | AS12: التشطيبات | AT12: 10 | AV12: Grand Total | AW12: 26 | AZ12: Supervisor
G13: فورمان | H13: 1680 | O13: FIN_D02 | P13: 7270.8333 | AI13: Grand Total | AJ13: 26 | AL13: معلم جبس بورد | AM13: 1 | AO13: Grand Total | AP13: 26 | AS13: Grand Total | AT13: 26 | AZ13: مشرف_موقع | BA13: 3400
G14: سائق | H14: 1934.5833 | O14: Grand Total | P14: 12846.25 | AL14: صباغ | AM14: 1 | AZ14: Worker
G15: عامل الثرى دى | H15: 4500 | AL15: فنى | AM15: 1 | AZ15: سائق | BA15: 1700
G16: Grand Total | H16: 12846.25 | AL16: معلم تشطيب | AM16: 1 | AZ16: سباك | BA16: 2600
AL17: فورمان | AM17: 2 | AZ17: صباغ | BA17: 1400
AL18: مساعد كهربائي | AM18: 2 | AZ18: عامل | BA18: 3500
AL19: عامل | AM19: 2 | AZ19: عامل الثرى دى | BA19: 4500
AL20: ناطور | AM20: 2 | AZ20: فنى | BA20: 2500
A21: Row Labels | B21: Net Salary | AL21: سباك | AM21: 2 | AZ21: فني بلاستر | BA21: 2500
A22: عبدالحكيم رستم انصاري | B22: 760.83333 | AL22: عامل الثرى دى | AM22: 2 | AZ22: فني عزل | BA22: 3500
A23: صلاح عبدالرحمن الحاج احمد | B23: 930 | AL23: كهربائي | AM23: 3 | AZ23: فورمان | BA23: 4000
A24: محمد اكبر صافي | B24: 1084.5833 | AL24: مشرف_موقع | AM24: 4 | AZ24: كهربائي | BA24: 5000
A25: محمد نور الأسلام | B25: 1450 | AL25: Grand Total | AM25: 26 | AZ25: مساعد كهربائي | BA25: 2700
A26: عبد الباسي عبد الرحمن اشير | B26: 1550 | AZ26: معلم تشطيب | BA26: 1700
A27: Grand Total | B27: 8775.4167 | AZ27: معلم جبس بورد | BA27: 1300
AZ28: ناطور | BA28: 3100
AZ29: Grand Total | BA29: 46600
AO30: Row Labels | AP30: Count of Emp_ID
AO31: إندونيسي – Indonesian | AP31: 1
AO32: أوغندي – Ugandan | AP32: 1
AO33: باكستاني – Pakistani | AP33: 4
AO34: تونسي – Tunisian | AP34: 2
AO35: فلبيني – Filipino | AP35: 2
AO36: مصري – Egyptian | AP36: 2
AO37: نيبالي – Nepali | AP37: 10
AO38: هندي – Indian | AP38: 4
AO39: Grand Total | AP39: 26
A48: Project Analysis
...

Sheet Departments
A1: 📋 Departments – جدول الأقسام
A2: م | B2: كود القسم | C2: اسم القسم بالعربي | D2: اسم القسم بالانجليزي | E2: ملاحظات
A3: # | B3: Dept_ID | C3: Dept_Name | D3: Dept_Name_EN | E3: Notes
A4: 1 | B4: ADM_D01 | C4: الإدارة | D4: Administration
A5: 2 | B5: FIN_D02 | C5: التشطيبات | D5: Finishes
A6: 3 | B6: CON_D03 | C6: الإنشاءات | D6: Construction
A7: 4 | B7: ELE_D04 | C7: الكهرباء | D7: electricity
A8: 5 | B8: PLM_D05 | C8: السباكة | D8: Plumbing
A9: 6 | B9: STN_D06 | C9: الحجر | D9: Stone
A10: 7 | B10: ALU_D07 | C10: الألمنيوم | D10: aluminum
A11: 8 | B11: EQP_D08 | C11: المعدات | D11: Equipment
A12: 9 | B12: CRP_D09 | C12: النجارة | D12: Carpentry
A13: 10 | B13: PTG_D10 | C13: الدهانات | D13: paints
A14: 11 | B14: All_D11 | C14: كل الأقسام | D14: All sections
A15: 12 | B15: D13
A16: 13 | B16: D14
A17: 14 | B17: D15

Sheet Projects
A1: 🏗️ Projects – سجل المشاريع
B2: كود المشروع | C2: اسم المشروع | D2: القسم | E2: الموقع | F2: تاريخ البدء | G2: تاريخ الانتهاء | H2: الحالة | J2: اسم العميل | K2: رقم الموبايل | L2: مسؤول_العميل | M2: ملاحظات
A3: # | B3: Project_ID | C3: Project_Name | D3: Department | E3: Location | F3: Start_Date | G3: End_Date | H3: Status | I3: Flag_Status | J3: Client_Name | K3: Contact_Number | L3: Client_Sales | M3: Notes
A4: 1 | B4: S001F | C4: سعود الفهد | D4: كل الأقسام | F4: 46095 | G4: 46097 | H4: جاري - Active | I4: =_xlfn.XLOOKUP(tbl_Projects[[#This Row],[Status]],Project_Status[Status],Project_Status[Flag],"",0) -> Ac_0
A5: 2 | B5: S002F | C5: سعيد صالح الجحيش | D5: كل الأقسام | F5: 46098 | G5: 46101 | H5: جاري - Active | I5: =_xlfn.XLOOKUP(tbl_Projects[[#This Row],[Status]],Project_Status[Status],Project_Status[Flag],"",0) -> Ac_0
A6: 3 | B6: CF0F | C6: الإنشاءات | D6: كل الأقسام | F6: 46103 | G6: 46107 | H6: جاري - Active | I6: =_xlfn.XLOOKUP(tbl_Projects[[#This Row],[Status]],Project_Status[Status],Project_Status[Flag],"",0) -> Ac_0
A7: 4 | B7: J001F | C7: جابر قحيز المري | D7: كل الأقسام | F7: 46100 | H7: جاري - Active | I7: =_xlfn.XLOOKUP(tbl_Projects[[#This Row],[Status]],Project_Status[Status],Project_Status[Flag],"",0) -> Ac_0
A8: 5 | B8: A001F | C8: عبدالعزيز قحيز المري | D8: كل الأقسام | H8: جاري - Active | I8: =_xlfn.XLOOKUP(tbl_Projects[[#This Row],[Status]],Project_Status[Status],Project_Status[Flag],"",0) -> Ac_0
A9: 6 | B9: H001F | C9: حمد خجيم عايض العذبة | D9: كل الأقسام | H9: مكتمل - Completed | I9: =_xlfn.XLOOKUP(tbl_Projects[[#This Row],[Status]],Project_Status[Status],Project_Status[Flag],"",0) -> Co_0
A10: 7 | B10: S003F | C10: سعود نقدان | D10: كل الأقسام | H10: مكتمل - Completed | I10: =_xlfn.XLOOKUP(tbl_Projects[[#This Row],[Status]],Project_Status[Status],Project_Status[Flag],"",0) -> Co_0
A11: 8 | B11: N001F | C11: ناصر الحايف | D11: كل الأقسام | H11: مكتمل - Completed | I11: =_xlfn.XLOOKUP(tbl_Projects[[#This Row],[Status]],Project_Status[Status],Project_Status[Flag],"",0) -> Co_0
A12: 9 | B12: S004F | C12: صالح العذبة | D12: كل الأقسام | H12: جاري - Active | I12: =_xlfn.XLOOKUP(tbl_Projects[[#This Row],[Status]],Project_Status[Status],Project_Status[Flag],"",0) -> Ac_0
A13: 10 | B13: A002F | C13: عبدالهادي الماجد | D13: كل الأقسام | H13: جاري - Active | I13: =_xlfn.XLOOKUP(tbl_Projects[[#This Row],[Status]],Project_Status[Status],Project_Status[Flag],"",0) -> Ac_0
A14: 11 | B14: EF0F | C14: مصطفى | D14: كل الأقسام | H14: جاري - Active | I14: =_xlfn.XLOOKUP(tbl_Projects[[#This Row],[Status]],Project_Status[Status],Project_Status[Flag],"",0) -> Ac_0
A15: 12 | B15: U001F | C15: عمير راشد المري | D15: كل الأقسام | H15: جاري - Active | I15: =_xlfn.XLOOKUP(tbl_Projects[[#This Row],[Status]],Project_Status[Status],Project_Status[Flag],"",0) -> Ac_0
A16: 13 | B16: H002F | C16: حمد راشد المري | D16: كل الأقسام | H16: جاري - Active | I16: =_xlfn.XLOOKUP(tbl_Projects[[#This Row],[Status]],Project_Status[Status],Project_Status[Flag],"",0) -> Ac_0
A17: 14 | B17: A003F | C17: علي فاران البريدي | D17: كل الأقسام | H17: جاري - Active | I17: =_xlfn.XLOOKUP(tbl_Projects[[#This Row],[Status]],Project_Status[Status],Project_Status[Flag],"",0) -> Ac_0
A18: 15 | B18: K001F | C18: خالد زاين الدوسري | D18: كل الأقسام | H18: جاري - Active | I18: =_xlfn.XLOOKUP(tbl_Projects[[#This Row],[Status]],Project_Status[Status],Project_Status[Flag],"",0) -> Ac_0
A19: 16 | B19: H003F | C19: حمد الشهوانى الهاجرى | D19: كل الأقسام | H19: جاري - Active | I19: =_xlfn.XLOOKUP(tbl_Projects[[#This Row],[Status]],Project_Status[Status],Project_Status[Flag],"",0) -> Ac_0
... A70: 67 | B70: J001C | C70: جابر سالم الغواص | D70: كل الأقسام | H70: مكتمل - Completed | I70: =_xlfn.XLOOKUP(tbl_Projects[[#This Row],[Status]],Project_Status[Status],Project_Status[Flag],"",0) -> Co_0

Sheet Master_Employee
A1: 👷 Master Employee – سجل بيانات الموظفين
A2: # | B2: 🔑 Key Info | H2: 👤 Personal Info | O2: 💼 Employment | Y2: 💰 Salary | AD2: ⏱ Hour Rates | AH2: 📊 Role | AI2: بيانات الكفالة
A3: م | B3: كود الموظف | C3: كود القسم | D3: القسم | E3: القسم بالانجليزي | F3: المشرف | H3: اسم الموظف بالعربي | I3: اسم الموظف بالانجليزي | J3: رقم الإقامة | K3: تاريج انتهاء الإقامة | L3: عدد الأيام من بعد انتهاء الإقامة | M3: الجنسية | N3: المهنة | O3: تاريخ تعيين | P3: تاريخ مباشرة العمل | Q3: تاريخ اخر مباشرة العمل | R3: حالة الموظف | S3: كود الحالة | T3: طريقة الدفع | U3: كود الدفع | V3: رقم حساب البنك | W3: عهدة الموظف | X3: ملاحظات | Y3: المرتب الأساسي | Z3: بدلات المعيشة | AA3: بدلات المواصلات | AB3: بدلات أخرى | AC3: المرتب الكلي | AD3: معدل اليوم | AE3: معدل الساعة العادية | AF3: معدل ساعة الوقت الإضافي | AG3: مضروب الوقت الإضافي | AH3: الدرجة | AI3: الكفالة | AJ3: اسم شركة الكفيل
A4: # | B4: Emp_ID | C4: Dept_ID | D4: Department | E4: Department_EN | F4: Supervisor_Name | G4: Supervisor_ID | H4: Name_AR | I4: Name_EN | J4: National_ID | K4: Q_ID_Expire_Date | L4: Residency_Days_Status | M4: Nationality | N4: Job_Title | O4: Hire_Date | P4: Join_Date | Q4: Last_Return_Date | R4: Emp_Status | S4: Status_Code | T4: Payment_Method | U4: Payment_Code | V4: Bank_Account_Number | W4: Employee_Assets | X4: Notes | Y4: Basic_Salary | Z4: Living_Allowance | AA4: Transport_Allowance | AB4: Other_Allowance | AC4: Total_Salary | AD4: Daily_Rate | AE4: Hour_Rate | AF4: OT_Hr_Rate | AG4: OT_Multiplier | AH4: Grade | AI4: sponsorship | AJ4: Name_of_sponsorship_company
A5: 1 | B5: =_xlfn.XLOOKUP(Master_Employee[[#This Row],[Name_AR]],Lists!AN:AN,Lists!AL:AL," ",0) -> O60 | C5: =_xlfn.XLOOKUP(Master_Employee[[#This Row],[Department]],tbl_Dept[Dept_Name],tbl_Dept[Dept_ID],"",0) -> CON_D03 | D5: الإنشاءات | E5: =_xlfn.XLOOKUP(Master_Employee[[#This Row],[Dept_ID]],tbl_Dept[Dept_ID],tbl_Dept[Dept_Name_EN],"",0) -> Construction | G5: =_xlfn.XLOOKUP(Master_Employee[[#This Row],[Supervisor_Name]],EmpNames,EmpIDs,"",0) | H5: محمد اكبر صافي | I5: =_xlfn.XLOOKUP(Master_Employee[[#This Row],[Emp_ID]],Lists!AL:AL,Lists!AO:AO,"",0) -> Muhammad Akbar Safi | J5: 299010001 | K5: 46122 | L5: =IF(Master_Employee[[#This Row],[Q_ID_Expire_Date]]="","",TODAY()-Master_Employee[[#This Row],[Q_ID_Expire_Date]]) -> 101 | M5: مصري – Egyptian | N5: سائق | O5: 44927 | R5: works - يعمل | S5: =_xlfn.XLOOKUP(Master_Employee[[#This Row],[Emp_Status]],Emp_Status[Emp_Status],Emp_Status[Status_Code],"",0) -> W_01 | T5: Vodafone - فودافون | U5: =_xlfn.XLOOKUP(Master_Employee[[#This Row],[Payment_Method]],Pay[Payment_Method],Pay[Pay_Code],"",0) -> V_0 | Y5: 1700 | AA5: 0 | AB5: 0 | AC5: =Master_Employee[[#This Row],[Basic_Salary]]+Master_Employee[[#This Row],[Living_Allowance]]+Master_Employee[[#This Row],[Transport_Allowance]]+Master_Employee[[#This Row],[Other_Allowance]] -> 1700 | AD5: =(Master_Employee[[#This Row],[Total_Salary]]/30) -> 56.666667 | AE5: =Master_Employee[[#This Row],[Daily_Rate]]/8 -> 7.0833333 | AF5: =(Master_Employee[[#This Row],[Basic_Salary]]/30/8)*(Master_Employee[[#This Row],[OT_Multiplier]]) -> 7.0833333 | AG5: =1 -> 1 | AH5: Worker | AI5: كفالة-Sponsership
A6: 2 | B6: =_xlfn.XLOOKUP(Master_Employee[[#This Row],[Name_AR]],Lists!AN:AN,Lists!AL:AL," ",0) -> O61 | C6: =_xlfn.XLOOKUP(Master_Employee[[#This Row],[Department]],tbl_Dept[Dept_Name],tbl_Dept[Dept_ID],"",0) -> CON_D03 | D6: الإنشاءات | E6: =_xlfn.XLOOKUP(Master_Employee[[#This Row],[Dept_ID]],tbl_Dept[Dept_ID],tbl_Dept[Dept_Name_EN],"",0) -> Construction | G6: =_xlfn.XLOOKUP(Master_Employee[[#This Row],[Supervisor_Name]],EmpNames,EmpIDs,"",0) | H6: عبدالحكيم رستم انصاري | I6: =_xlfn.XLOOKUP(Master_Employee[[#This Row],[Emp_ID]],Lists!AL:AL,Lists!AO:AO,"",0) -> Abdul Hakim Rustam Ansari | J6: 299010002 | K6: 46116 | L6: =IF(Master_Employee[[#This Row],[Q_ID_Expire_Date]]="","",TODAY()-Master_Employee[[#This Row],[Q_ID_Expire_Date]]) -> 107 | M6: مصري – Egyptian | N6: مشرف_موقع | O6: 01/03/2023 | R6: works - يعمل | S6: =_xlfn.XLOOKUP(Master_Employee[[#This Row],[Emp_Status]],Emp_Status[Emp_Status],Emp_Status[Status_Code],"",0) -> W_01 | T6: Vodafone - فودافون | U6: =_xlfn.XLOOKUP(Master_Employee[[#This Row],[Payment_Method]],Pay[Payment_Method],Pay[Pay_Code],"",0) -> V_0 | Y6: 1400 | AA6: 0 | AB6: 0 | AC6: =Master_Employee[[#This Row],[Basic_Salary]]+Master_Employee[[#This Row],[Living_Allowance]]+Master_Employee[[#This Row],[Transport_Allowance]]+Master_Employee[[#This Row],[Other_Allowance]] -> 1400 | AD6: =(Master_Employee[[#This Row],[Total_Salary]]/30) -> 46.666667 | AE6: =Master_Employee[[#This Row],[Daily_Rate]]/8 -> 5.8333333 | AF6: =(Master_Employee[[#This Row],[Basic_Salary]]/30/8)*(Master_Employee[[#This Row],[OT_Multiplier]]) -> 5.8333333 | AG6: =1 -> 1 | AH6: Supervisor | AI6: كفالة-Sponsership
A7: 3 | B7: =_xlfn.XLOOKUP(Master_Employee[[#This Row],[Name_AR]],Lists!AN:AN,Lists!AL:AL," ",0) -> O52 | C7: =_xlfn.XLOOKUP(Master_Employee[[#This Row],[Department]],tbl_Dept[Dept_Name],tbl_Dept[Dept_ID],"",0) -> CON_D03 | D7: الإنشاءات | E7: =_xlfn.XLOOKUP(Master_Employee[[#This Row],[Dept_ID]],tbl_Dept[Dept_ID],tbl_Dept[Dept_Name_EN],"",0) -> Construction | G7: =_xlfn.XLOOKUP(Master_Employee[[#This Row],[Supervisor_Name]],EmpNames,EmpIDs,"",0) | H7: شميم انصاري | I7: =_xlfn.XLOOKUP(Master_Employee[[#This Row],[Emp_ID]],Lists!AL:AL,Lists!AO:AO,"",0) -> Shamim Ansari | J7: 299010003 | K7: 46123 | L7: =IF(Master_Employee[[#This Row],[Q_ID_Expire_Date]]="","",TODAY()-Master_Employee[[#This Row],[Q_ID_Expire_Date]]) -> 100 | M7: هندي – Indian | N7: مشرف_موقع | O7: 15/04/2023 | R7: vacation - إجازة | S7: =_xlfn.XLOOKUP(Master_Employee[[#This Row],[Emp_Status]],Emp_Status[Emp_Status],Emp_Status[Status_Code],"",0) -> V_01 | T7: Vodafone - فودافون | U7: =_xlfn.XLOOKUP(Master_Employee[[#This Row],[Payment_Method]],Pay[Payment_Method],Pay[Pay_Code],"",0) -> V_0 | Y7: 2000 | AA7: 0 | AB7: 0 | AC7: =Master_Employee[[#This Row],[Basic_Salary]]+Master_Employee[[#This Row],[Living_Allowance]]+Master_Employee[[#This Row],[Transport_Allowance]]+Master_Employee[[#This Row],[Other_Allowance]] -> 2000 | AD7: =(Master_Employee[[#This Row],[Total_Salary]]/30) -> 66.666667 | AE7: =Master_Employee[[#This Row],[Daily_Rate]]/8 -> 8.3333333 | AF7: =(Master_Employee[[#This Row],[Basic_Salary]]/30/8)*(Master_Employee[[#This Row],[OT_Multiplier]]) -> 8.3333333 | AG7: =1 -> 1 | AH7: Supervisor | AI7: كفالة-Sponsership
A8: 4 | B8: =_xlfn.XLOOKUP(Master_Employee[[#This Row],[Name_AR]],Lists!AN:AN,Lists!AL:AL," ",0) -> O162 | C8: =_xlfn.XLOOKUP(Master_Employee[[#This Row],[Department]],tbl_Dept[Dept_Name],tbl_Dept[Dept_ID],"",0) -> CON_D03 | D8: الإنشاءات | E8: =_xlfn.XLOOKUP(Master_Employee[[#This Row],[Dept_ID]],tbl_Dept[Dept_ID],tbl_Dept[Dept_Name_EN],"",0) -> Construction | G8: =_xlfn.XLOOKUP(Master_Employee[[#This Row],[Supervisor_Name]],EmpNames,EmpIDs,"",0) | H8: يرافن انصاري | I8: =_xlfn.XLOOKUP(Master_Employee[[#This Row],[Emp_ID]],Lists!AL:AL,Lists!AO:AO,"",0) -> Yaraven Ansari | J8: 299010101 | K8: 46124 | L8: =IF(Master_Employee[[#This Row],[Q_ID_Expire_Date]]="","",TODAY()-Master_Employee[[#This Row],[Q_ID_Expire_Date]]) -> 99 | M8: هندي – Indian | N8: مشرف_موقع | O8: 01/05/2023 | R8: vacation - إجازة | S8: =_xlfn.XLOOKUP(Master_Employee[[#This Row],[Emp_Status]],Emp_Status[Emp_Status],Emp_Status[Status_Code],"",0) -> V_01 | T8: Bank - بنك | U8: =_xlfn.XLOOKUP(Master_Employee[[#This Row],[Payment_Method]],Pay[Payment_Method],Pay[Pay_Code],"",0) -> B_0 | Y8: 1500 | AA8: 300 | AB8: 0 | AC8: =Master_Employee[[#This Row],[Basic_Salary]]+Master_Employee[[#This Row],[Living_Allowance]]+Master_Employee[[#This Row],[Transport_Allowance]]+Master_Employee[[#This Row],[Other_Allowance]] -> 1800 | AD8: =(Master_Employee[[#This Row],[Total_Salary]]/30) -> 60 | AE8: =Master_Employee[[#This Row],[Daily_Rate]]/8 -> 7.5 | AF8: =(Master_Employee[[#This Row],[Basic_Salary]]/30/8)*(Master_Employee[[#This Row],[OT_Multiplier]]) -> 6.25 | AG8: =1 -> 1 | AH8: Manager | AI8: كفالة-Sponsership
A9: 5 | B9: =_xlfn.XLOOKUP(Master_Employee[[#This Row],[Name_AR]],Lists!AN:AN,Lists!AL:AL," ",0) -> O175 | C9: =_xlfn.XLOOKUP(Master_Employee[[#This Row],[Department]],tbl_Dept[Dept_Name],tbl_Dept[Dept_ID],"",0) -> CON_D03 | D9: الإنشاءات | E9: =_xlfn.XLOOKUP(Master_Employee[[#This Row],[Dept_ID]],tbl_Dept[Dept_ID],tbl_Dept[Dept_Name_EN],"",0) -> Construction | G9: =_xlfn.XLOOKUP(Master_Employee[[#This Row],[Supervisor_Name]],EmpNames,EmpIDs,"",0) | H9: انوار انصاري رحيم انصاري | I9: =_xlfn.XLOOKUP(Master_Employee[[#This Row],[Emp_ID]],Lists!AL:AL,Lists!AO:AO,"",0) -> Anwar Ansari Rahim Ansari | J9: 299010202 | K9: 46125 | L9: =IF(Master_Employee[[#This Row],[Q_ID_Expire_Date]]="","",TODAY()-Master_Employee[[#This Row],[Q_ID_Expire_Date]]) -> 98 | M9: هندي – Indian | N9: مشرف_موقع | O9: 01/06/2023 | R9: works - يعمل | S9: =_xlfn.XLOOKUP(Master_Employee[[#This Row],[Emp_Status]],Emp_Status[Emp_Status],Emp_Status[Status_Code],"",0) -> W_01 | T9: cash - نقدا | U9: =_xlfn.XLOOKUP(Master_Employee[[#This Row],[Payment_Method]],Pay[Payment_Method],Pay[Pay_Code],"",0) -> C_0 | Y9: 1100 | AA9: 300 | AB9: 0 | AC9: =Master_Employee[[#This Row],[Basic_Salary]]+Master_Employee[[#This Row],[Living_Allowance]]+Master_Employee[[#This Row],[Transport_Allowance]]+Master_Employee[[#This Row],[Other_Allowance]] -> 1400 | AD9: =(Master_Employee[[#This Row],[Total_Salary]]/30) -> 46.666667 | AE9: =Master_Employee[[#This Row],[Daily_Rate]]/8 -> 5.8333333 | AF9: =(Master_Employee[[#This Row],[Basic_Salary]]/30/8)*(Master_Employee[[#This Row],[OT_Multiplier]]) -> 4.5833333 | AG9: =1 -> 1 | AH9: Manager | AI9: كفالة-Sponsership
A10: 6 | B10: =_xlfn.XLOOKUP(Master_Employee[[#This Row],[Name_AR]],Lists!AN:AN,Lists!AL:AL," ",0) -> O180 | C10: =_xlfn.XLOOKUP(Master_Employee[[#This Row],[Department]],tbl_Dept[Dept_Name],tbl_Dept[Dept_ID],"",0) -> CON_D03 | D10: الإنشاءات | E10: =_xlfn.XLOOKUP(Master_Employee[[#This Row],[Dept_ID]],tbl_Dept[Dept_ID],tbl_Dept[Dept_Name_EN],"",0) -> Construction | G10: =_xlfn.XLOOKUP(Master_Employee[[#This Row],[Supervisor_Name]],EmpNames,EmpIDs,"",0) | H10: جسير انصاري | I10: =_xlfn.XLOOKUP(Master_Employee[[#This Row],[Emp_ID]],Lists!AL:AL,Lists!AO:AO,"",0) -> Jasser Ansari | J10: 299010303 | K10: 46157 | L10: =IF(Master_Employee[[#This Row],[Q_ID_Expire_Date]]="","",TODAY()-Master_Employee[[#This Row],[Q_ID_Expire_Date]]) -> 66 | M10: هندي – Indian | N10: سباك | O10: 10/07/2023 | R10: works - يعمل | S10: =_xlfn.XLOOKUP(Master_Employee[[#This Row],[Emp_Status]],Emp_Status[Emp_Status],Emp_Status[Status_Code],"",0) -> W_01 | T10: Vodafone - فودافون | U10: =_xlfn.XLOOKUP(Master_Employee[[#This Row],[Payment_Method]],Pay[Payment_Method],Pay[Pay_Code],"",0) -> V_0 | Y10: 1000 | AA10: 300 | AB10: 0 | AC10: =Master_Employee[[#This Row],[Basic_Salary]]+Master_Employee[[#This Row],[Living_Allowance]]+Master_Employee[[#This Row],[Transport_Allowance]]+Master_Employee[[#This Row],[Other_Allowance]] -> 1300 | AD10: =(Master_Employee[[#This Row],[Total_Salary]]/30) -> 43.333333 | AE10: =Master_Employee[[#This Row],[Daily_Rate]]/8 -> 5.4166667 | AF10: =(Master_Employee[[#This Row],[Basic_Salary]]/30/8)*(Master_Employee[[#This Row],[OT_Multiplier]]) -> 4.1666667 | AG10: =1 -> 1 | AH10: Worker | AI10: غير كفالة-NoSponsership
A11: 7 | B11: =_xlfn.XLOOKUP(Master_Employee[[#This Row],[Name_AR]],Lists!AN:AN,Lists!AL:AL," ",0) -> O183 | C11: =_xlfn.XLOOKUP(Master_Employee[[#This Row],[Department]],tbl_Dept[Dept_Name],tbl_Dept[Dept_ID],"",0) -> CON_D03 | D11: الإنشاءات | E11: =_xlfn.XLOOKUP(Master_Employee[[#This Row],[Dept_ID]],tbl_Dept[Dept_ID],tbl_Dept[Dept_Name_EN],"",0) -> Construction | G11: =_xlfn.XLOOKUP(Master_Employee[[#This Row],[Supervisor_Name]],EmpNames,EmpIDs,"",0) | H11: محمد عمران انصاري | I11: =_xlfn.XLOOKUP(Master_Employee[[#This Row],[Emp_ID]],Lists!AL:AL,Lists!AO:AO,"",0) -> Muhammad Imran Ansari | J11: 299010404 | K11: 46218 | L11: =IF(Master_Employee[[#This Row],[Q_ID_Expire_Date]]="","",TODAY()-Master_Employee[[#This Row],[Q_ID_Expire_Date]]) -> 5 | M11: باكستاني – Pakistani | N11: عامل | O11: 01/08/2023 | R11: vacation - إجازة | S11: =_xlfn.XLOOKUP(Master_Employee[[#This Row],[Emp_Status]],Emp_Status[Emp_Status],Emp_Status[Status_Code],"",0) -> V_01 | T11: cash - نقدا | U11: =_xlfn.XLOOKUP(Master_Employee[[#This Row],[Payment_Method]],Pay[Payment_Method],Pay[Pay_Code],"",0) -> C_0 | Y11: 1700 | AA11: 300 | AB11: 200 | AC11: =Master_Employee[[#This Row],[Basic_Salary]]+Master_Employee[[#This Row],[Living_Allowance]]+Master_Employee[[#This Row],[Transport_Allowance]]+Master_Employee[[#This Row],[Other_Allowance]] -> 2200 | AD11: =(Master_Employee[[#This Row],[Total_Salary]]/30) -> 73.333333 | AE11: =Master_Employee[[#This Row],[Daily_Rate]]/8 -> 9.1666667 | AF11: =(Master_Employee[[#This Row],[Basic_Salary]]/30/8)*(Master_Employee[[#This Row],[OT_Multiplier]]) -> 7.0833333 | AG11: =1 -> 1 | AH11: Worker | AI11: غير كفالة-NoSponsership
A12: 8 | B12: =_xlfn.XLOOKUP(Master_Employee[[#This Row],[Name_AR]],Lists!AN:AN,Lists!AL:AL," ",0) -> O201 | C12: =_xlfn.XLOOKUP(Master_Employee[[#This Row],[Department]],tbl_Dept[Dept_Name],tbl_Dept[Dept_ID],"",0) -> CON_D03 | D12: الإنشاءات | E12: =_xlfn.XLOOKUP(Master_Employee[[#This Row],[Dept_ID]],tbl_Dept[Dept_ID],tbl_Dept[Dept_Name_EN],"",0) -> Construction | G12: =_xlfn.XLOOKUP(Master_Employee[[#This Row],[Supervisor_Name]],EmpNames,EmpIDs,"",0) | H12: محمد ياسين تورب علي | I12: =_xlfn.XLOOKUP(Master_Employee[[#This Row],[Emp_ID]],Lists!AL:AL,Lists!AO:AO,"",0) -> Mohammed Yassin Torb Ali | J12: 299010505 | L12: =IF(Master_Employee[[#This Row],[Q_ID_Expire_Date]]="","",TODAY()-Master_Employee[[#This Row],[Q_ID_Expire_Date]]) | M12: باكستاني – Pakistani | N12: كهربائي | O12: 01/09/2023 | R12: works - يعمل | S12: =_xlfn.XLOOKUP(Master_Employee[[#This Row],[Emp_Status]],Emp_Status[Emp_Status],Emp_Status[Status_Code],"",0) -> W_01 | T12: Bank - بنك | U12: =_xlfn.XLOOKUP(Master_Employee[[#This Row],[Payment_Method]],Pay[Payment_Method],Pay[Pay_Code],"",0) -> B_0 | Y12: 1000 | AA12: 300 | AB12: 100 | AC12: =Master_Employee[[#This Row],[Basic_Salary]]+Master_Employee[[#This Row],[Living_Allowance]]+Master_Employee[[#This Row],[Transport_Allowance]]+Master_Employee[[#This Row],[Other_Allowance]] -> 1400 | AD12: =(Master_Employee[[#This Row],[Total_Salary]]/30) -> 46.666667 | AE12: =Master_Employee[[#This Row],[Daily_Rate]]/8 -> 5.8333333 | AF12: =(Master_Employee[[#This Row],[Basic_Salary]]/30/8)*(Master_Employee[[#This Row],[OT_Multiplier]]) -> 4.1666667 | AG12: =1 -> 1 | AH12: Worker | AI12: غير كفالة-NoSponsership
A13: 9 | B13: =_xlfn.XLOOKUP(Master_Employee[[#This Row],[Name_AR]],Lists!AN:AN,Lists!AL:AL," ",0) -> O229 | C13: =_xlfn.XLOOKUP(Master_Employee[[#This Row],[Department]],tbl_Dept[Dept_Name],tbl_Dept[Dept_ID],"",0) -> CON_D03 | D13: الإنشاءات | E13: =_xlfn.XLOOKUP(Master_Employee[[#This Row],[Dept_ID]],tbl_Dept[Dept_ID],tbl_Dept[Dept_Name_EN],"",0) -> Construction | G13: =_xlfn.XLOOKUP(Master_Employee[[#This Row],[Supervisor_Name]],EmpNames,EmpIDs,"",0) | H13: محمد سهيل محمد سليم | I13: =_xlfn.XLOOKUP(Master_Employee[[#This Row],[Emp_ID]],Lists!AL:AL,Lists!AO:AO,"",0) -> Mohammed Suhail Mohammed Salim | J13: 299010606 | L13: =IF(Master_Employee[[#This Row],[Q_ID_Expire_Date]]="","",TODAY()-Master_Employee[[#This Row],[Q_ID_Expire_Date]]) | M13: باكستاني – Pakistani | N13: مساعد كهربائي | O13: 15/01/2024 | R13: works - يعمل | S13: =_xlfn.XLOOKUP(Master_Employee[[#This Row],[Emp_Status]],Emp_Status[Emp_Status],Emp_Status[Status_Code],"",0) -> W_01 | T13: cash - نقدا | U13: =_xlfn.XLOOKUP(Master_Employee[[#This Row],[Payment_Method]],Pay[Payment_Method],Pay[Pay_Code],"",0) -> C_0 | Y13: 1000 | AA13: 300 | AB13: 100 | AC13: =Master_Employee[[#This Row],[Basic_Salary]]+Master_Employee[[#This Row],[Living_Allowance]]+Master_Employee[[#This Row],[Transport_Allowance]]+Master_Employee[[#This Row],[Other_Allowance]] -> 1400 | AD13: =(Master_Employee[[#This Row],[Total_Salary]]/30) -> 46.666667 | AE13: =Master_Employee[[#This Row],[Daily_Rate]]/8 -> 5.8333333 | AF13: =(Master_Employee[[#This Row],[Basic_Salary]]/30/8)*(Master_Employee[[#This Row],[OT_Multiplier]]) -> 4.1666667 | AG13: =1 -> 1 | AH13: Worker | AI13: غير كفالة-NoSponsership
A14: 10 | B14: =_xlfn.XLOOKUP(Master_Employee[[#This Row],[Name_AR]],Lists!AN:AN,Lists!AL:AL," ",0) -> 244 | C14: =_xlfn.XLOOKUP(Master_Employee[[#This Row],[Department]],tbl_Dept[Dept_Name],tbl_Dept[Dept_ID],"",0) -> CON_D03 | D14: الإنشاءات | E14: =_xlfn.XLOOKUP(Master_Employee[[#This Row],[Dept_ID]],tbl_Dept[Dept_ID],tbl_Dept[Dept_Name_EN],"",0) -> Construction | G14: =_xlfn.XLOOKUP(Master_Employee[[#This Row],[Supervisor_Name]],EmpNames,EmpIDs,"",0) | H14: جمال انصاري | I14: =_xlfn.XLOOKUP(Master_Employee[[#This Row],[Emp_ID]],Lists!AL:AL,Lists!AO:AO,"",0) -> Jamal Ansari | J14: 299010707 | L14: =IF(Master_Employee[[#This Row],[Q_ID_Expire_Date]]="","",TODAY()-Master_Employee[[#This Row],[Q_ID_Expire_Date]]) | M14: باكستاني – Pakistani | N14: كهربائي | O14: 01/02/2024 | R14: works - يعمل | S14: =_xlfn.XLOOKUP(Master_Employee[[#This Row],[Emp_Status]],Emp_Status[Emp_Status],Emp_Status[Status_Code],"",0) -> W_01 | T14: cash - نقدا | U14: =_xlfn.XLOOKUP(Master_Employee[[#This Row],[Payment_Method]],Pay[Payment_Method],Pay[Pay_Code],"",0) -> C_0 | Y14: 1200 | AA14: 300 | AB14: 100 | AC14: =Master_Employee[[#This Row],[Basic_Salary]]+Master_Employee[[#This Row],[Living_Allowance]]+Master_Employee[[#This Row],[Transport_Allowance]]+Master_Employee[[#This Row],[Other_Allowance]] -> 1600 | AD14: =(Master_Employee[[#This Row],[Total_Salary]]/30) -> 53.333333 | AE14: =Master_Employee[[#This Row],[Daily_Rate]]/8 -> 6.6666667 | AF14: =(Master_Employee[[#This Row],[Basic_Salary]]/30/8)*(Master_Employee[[#This Row],[OT_Multiplier]]) -> 5 | AG14: =1 -> 1 | AH14: Worker | AI14: غير كفالة-NoSponsership
A15: 11 | B15: =_xlfn.XLOOKUP(Master_Employee[[#This Row],[Name_AR]],Lists!AN:AN,Lists!AL:AL," ",0) -> 243 | C15: =_xlfn.XLOOKUP(Master_Employee[[#This Row],[Department]],tbl_Dept[Dept_Name],tbl_Dept[Dept_ID],"",0) -> FIN_D02 | D15: التشطيبات | E15: =_xlfn.XLOOKUP(Master_Employee[[#This Row],[Dept_ID]],tbl_Dept[Dept_ID],tbl_Dept[Dept_Name_EN],"",0) -> Finishes | G15: =_xlfn.XLOOKUP(Master_Employee[[#This Row],[Supervisor_Name]],EmpNames,EmpIDs,"",0) | H15: محمد عزيز لاحق | I15: =_xlfn.XLOOKUP(Master_Employee[[#This Row],[Emp_ID]],Lists!AL:AL,Lists!AO:AO,"",0) -> 0 | L15: =IF(Master_Employee[[#This Row],[Q_ID_Expire_Date]]="","",TODAY()-Master_Employee[[#This Row],[Q_ID_Expire_Date]]) | M15: نيبالي – Nepali | N15: صباغ | R15: works - يعمل | S15: =_xlfn.XLOOKUP(Master_Employee[[#This Row],[Emp_Status]],Emp_Status[Emp_Status],Emp_Status[Status_Code],"",0) -> W_01 | T15: Bank - بنك | U15: =_xlfn.XLOOKUP(Master_Employee[[#This Row],[Payment_Method]],Pay[Payment_Method],Pay[Pay_Code],"",0) -> B_0 | Y15: 1000 | AA15: 300 | AB15: 100 | AC15: =Master_Employee[[#This Row],[Basic_Salary]]+Master_Employee[[#This Row],[Living_Allowance]]+Master_Employee[[#This Row],[Transport_Allowance]]+Master_Employee[[#This Row],[Other_Allowance]] -> 1400 | AD15: =(Master_Employee[[#This Row],[Total_Salary]]/30) -> 46.666667 | AE15: =Master_Employee[[#This Row],[Daily_Rate]]/8 -> 5.8333333 | AF15: =(Master_Employee[[#This Row],[Basic_Salary]]/30/8)*(Master_Employee[[#This Row],[OT_Multiplier]]) -> 4.1666667 | AG15: =1 -> 1 | AH15: Worker | AI15: غير كفالة-NoSponsership
A16: 12 | B16: =_xlfn.XLOOKUP(Master_Employee[[#This Row],[Name_AR]],Lists!AN:AN,Lists!AL:AL," ",0) -> 389 | C16: =_xlfn.XLOOKUP(Master_Employee[[#This Row],[Department]],tbl_Dept[Dept_Name],tbl_Dept[Dept_ID],"",0) -> FIN_D02 | D16: التشطيبات | E16: =_xlfn.XLOOKUP(Master_Employee[[#This Row],[Dept_ID]],tbl_Dept[Dept_ID],tbl_Dept[Dept_Name_EN],"",0) -> Finishes | G16: =_xlfn.XLOOKUP(Master_Employee[[#This Row],[Supervisor_Name]],EmpNames,EmpIDs,"",0) | H16: محمد نور نبي | I16: =_xlfn.XLOOKUP(Master_Employee[[#This Row],[Emp_ID]],Lists!AL:AL,Lists!AO:AO,"",0) -> 0 | L16: =IF(Master_Employee[[#This Row],[Q_ID_Expire_Date]]="","",TODAY()-Master_Employee[[#This Row],[Q_ID_Expire_Date]]) | M16: نيبالي – Nepali | N16: مساعد كهربائي | R16: works - يعمل | S16: =_xlfn.XLOOKUP(Master_Employee[[#This Row],[Emp_Status]],Emp_Status[Emp_Status],Emp_Status[Status_Code],"",0) -> W_01 | T16: Bank - بنك | U16: =_xlfn.XLOOKUP(Master_Employee[[#This Row],[Payment_Method]],Pay[Payment_Method],Pay[Pay_Code],"",0) -> B_0 | Y16: 1000 | AA16: 300 | AB16: 0 | AC16: =Master_Employee[[#This Row],[Basic_Salary]]+Master_Employee[[#This Row],[Living_Allowance]]+Master_Employee[[#This Row],[Transport_Allowance]]+Master_Employee[[#This Row],[Other_Allowance]] -> 1300 | AD16: =(Master_Employee[[#This Row],[Total_Salary]]/30) -> 43.333333 | AE16: =Master_Employee[[#This Row],[Daily_Rate]]/8 -> 5.4166667 | AF16: =(Master_Employee[[#This Row],[Basic_Salary]]/30/8)*(Master_Employee[[#This Row],[OT_Multiplier]]) -> 4.1666667 | AG16: =1 -> 1 | AH16: Worker | AI16: غير كفالة-NoSponsership
A17: 13 | B17: =_xlfn.XLOOKUP(Master_Employee[[#This Row],[Name_AR]],Lists!AN:AN,Lists!AL:AL," ",0) -> 411 | C17: =_xlfn.XLOOKUP(Master_Employee[[#This Row],[Department]],tbl_Dept[Dept_Name],tbl_Dept[Dept_ID],"",0) -> FIN_D02 | D17: التشطيبات | E17: =_xlfn.XLOOKUP(Master_Employee[[#This Row],[Dept_ID]],tbl_Dept[Dept_ID],tbl_Dept[Dept_Name_EN],"",0) -> Finishes | G17: =_xlfn.XLOOKUP(Master_Employee[[#This Row],[Supervisor_Name]],EmpNames,EmpIDs,"",0) | H17: نور ميستري | I17: =_xlfn.XLOOKUP(Master_Employee[[#This Row],[Emp_ID]],Lists!AL:AL,Lists!AO:AO,"",0) -> 0 | L17: =IF(Master_Employee[[#This Row],[Q_ID_Expire_Date]]="","",TODAY()-Master_Employee[[#This Row],[Q_ID_Expire_Date]]) | M17: نيبالي – Nepali | N17: سباك | R17: works - يعمل | S17: =_xlfn.XLOOKUP(Master_Employee[[#This Row],[Emp_Status]],Emp_Status[Emp_Status],Emp_Status[Status_Code],"",0) -> W_01 | T17: Bank - بنك | U17: =_xlfn.XLOOKUP(Master_Employee[[#This Row],[Payment_Method]],Pay[Payment_Method],Pay[Pay_Code],"",0) -> B_0 | Y17: 1000 | AA17: 300 | AB17: 0 | AC17: =Master_Employee[[#This Row],[Basic_Salary]]+Master_Employee[[#This Row],[Living_Allowance]]+Master_Employee[[#This Row],[Transport_Allowance]]+Master_Employee[[#This Row],[Other_Allowance]] -> 1300 | AD17: =(Master_Employee[[#This Row],[Total_Salary]]/30) -> 43.333333 | AE17: =Master_Employee[[#This Row],[Daily_Rate]]/8 -> 5.4166667 | AF17: =(Master_Employee[[#This Row],[Basic_Salary]]/30/8)*(Master_Employee[[#This Row],[OT_Multiplier]]) -> 4.1666667 | AG17: =1 -> 1 | AH17: Worker | AI17: غير كفالة-NoSponsership
A18: 14 | B18: =_xlfn.XLOOKUP(Master_Employee[[#This Row],[Name_AR]],Lists!AN:AN,Lists!AL:AL," ",0) -> 448 | C18: =_xlfn.XLOOKUP(Master_Employee[[#This Row],[Department]],tbl_Dept[Dept_Name],tbl_Dept[Dept_ID],"",0) -> FIN_D02 | D18: التشطيبات | E18: =_xlfn.XLOOKUP(Master_Employee[[#This Row],[Dept_ID]],tbl_Dept[Dept_ID],tbl_Dept[Dept_Name_EN],"",0) -> Finishes | G18: =_xlfn.XLOOKUP(Master_Employee[[#This Row],[Supervisor_Name]],EmpNames,EmpIDs,"",0) | H18: بابو رام كامي | I18: =_xlfn.XLOOKUP(Master_Employee[[#This Row],[Emp_ID]],Lists!AL:AL,Lists!AO:AO,"",0) -> 0 | L18: =IF(Master_Employee[[#This Row],[Q_ID_Expire_Date]]="","",TODAY()-Master_Employee[[#This Row],[Q_ID_Expire_Date]]) | M18: نيبالي – Nepali | N18: كهربائي | R18: works - يعمل | S18: =_xlfn.XLOOKUP(Master_Employee[[#This Row],[Emp_Status]],Emp_Status[Emp_Status],Emp_Status[Status_Code],"",0) -> W_01 | T18: Bank - بنك | U18: =_xlfn.XLOOKUP(Master_Employee[[#This Row],[Payment_Method]],Pay[Payment_Method],Pay[Pay_Code],"",0) -> B_0 | Y18: 1500 | AA18: 500 | AB18: 0 | AC18: =Master_Employee[[#This Row],[Basic_Salary]]+Master_Employee[[#This Row],[Living_Allowance]]+Master_Employee[[#This Row],[Transport_Allowance]]+Master_Employee[[#This Row],[Other_Allowance]] -> 2000 | AD18: =(Master_Employee[[#This Row],[Total_Salary]]/30) -> 66.666667 | AE18: =Master_Employee[[#This Row],[Daily_Rate]]/8 -> 8.3333333 | AF18: =(Master_Employee[[#This Row],[Basic_Salary]]/30/8)*(Master_Employee[[#This Row],[OT_Multiplier]]) -> 6.25 | AG18: =1 -> 1 | AH18: Worker | AI18: كفالة-Sponsership
A19: 15 | B19: =_xlfn.XLOOKUP(Master_Employee[[#This Row],[Name_AR]],Lists!AN:AN,Lists!AL:AL," ",0) -> 247 | C19: =_xlfn.XLOOKUP(Master_Employee[[#This Row],[Department]],tbl_Dept[Dept_Name],tbl_Dept[Dept_ID],"",0) -> FIN_D02 | D19: التشطيبات | E19: =_xlfn.XLOOKUP(Master_Employee[[#This Row],[Dept_ID]],tbl_Dept[Dept_ID],tbl_Dept[Dept_Name_EN],"",0) -> Finishes | G19: =_xlfn.XLOOKUP(Master_Employee[[#This Row],[Supervisor_Name]],EmpNames,EmpIDs,"",0) | H19: جمال محمد علي | I19: =_xlfn.XLOOKUP(Master_Employee[[#This Row],[Emp_ID]],Lists!AL:AL,Lists!AO:AO,"",0) -> 0 | L19: =IF(Master_Employee[[#This Row],[Q_ID_Expire_Date]]="","",TODAY()-Master_Employee[[#This Row],[Q_ID_Expire_Date]]) | M19: نيبالي – Nepali | N19: معلم جبس بورد | R19: works - يعمل | S19: =_xlfn.XLOOKUP(Master_Employee[[#This Row],[Emp_Status]],Emp_Status[Emp_Status],Emp_Status[Status_Code],"",0) -> W_01 | T19: cash - نقدا | U19: =_xlfn.XLOOKUP(Master_Employee[[#This Row],[Payment_Method]],Pay[Payment_Method],Pay[Pay_Code],"",0) -> C_0 | Y19: 1000 | AA19: 0 | AB19: 300 | AC19: =Master_Employee[[#This Row],[Basic_Salary]]+Master_Employee[[#This Row],[Living_Allowance]]+Master_Employee[[#This Row],[Transport_Allowance]]+Master_Employee[[#This Row],[Other_Allowance]] -> 1300 | AD19: =(Master_Employee[[#This Row],[Total_Salary]]/30) -> 43.333333 | AE19: =Master_Employee[[#This Row],[Daily_Rate]]/8 -> 5.4166667 | AF19: =(Master_Employee[[#This Row],[Basic_Salary]]/30/8)*(Master_Employee[[#This Row],[OT_Multiplier]]) -> 4.1666667 | AG19: =1 -> 1 | AH19: Worker | AI19: كفالة-Sponsership
A20: 16 | B20: =_xlfn.XLOOKUP(Master_Employee[[#This Row],[Name_AR]],Lists!AN:AN,Lists!AL:AL," ",0) -> O204 | C20: =_xlfn.XLOOKUP(Master_Employee[[#This Row],[Department]],tbl_Dept[Dept_Name],tbl_Dept[Dept_ID],"",0) -> FIN_D02 | D20: التشطيبات | E20: =_xlfn.XLOOKUP(Master_Employee[[#This Row],[Dept_ID]],tbl_Dept[Dept_ID],tbl_Dept[Dept_Name_EN],"",0) -> Finishes | G20: =_xlfn.XLOOKUP(Master_Employee[[#This Row],[Supervisor_Name]],EmpNames,EmpIDs,"",0) | H20: محمد ابوبكور محمد حسين | I20: =_xlfn.XLOOKUP(Master_Employee[[#This Row],[Emp_ID]],Lists!AL:AL,Lists!AO:AO,"",0) -> 0 | L20: =IF(Master_Employee[[#This Row],[Q_ID_Expire_Date]]="","",TODAY()-Master_Employee[[#This Row],[Q_ID_Expire_Date]]) | M20: نيبالي – Nepali | N20: فورمان | R20: works - يعمل | S20: =_xlfn.XLOOKUP(Master_Employee[[#This Row],[Emp_Status]],Emp_Status[Emp_Status],Emp_Status[Status_Code],"",0) -> W_01 | T20: cash - نقدا | U20: =_xlfn.XLOOKUP(Master_Employee[[#This Row],[Payment_Method]],Pay[Payment_Method],Pay[Pay_Code],"",0) -> C_0 | Y20: 1700 | AA20: 300 | AB20: 200 | AC20: =Master_Employee[[#This Row],[Basic_Salary]]+Master_Employee[[#This Row],[Living_Allowance]]+Master_Employee[[#This Row],[Transport_Allowance]]+Master_Employee[[#This Row],[Other_Allowance]] -> 2200 | AD20: =(Master_Employee[[#This Row],[Total_Salary]]/30) -> 73.333333 | AE20: =Master_Employee[[#This Row],[Daily_Rate]]/8 -> 9.1666667 | AF20: =(Master_Employee[[#This Row],[Basic_Salary]]/30/8)*(Master_Employee[[#This Row],[OT_Multiplier]]) -> 7.0833333 | AG20: =1 -> 1 | AH20: Worker | AI20: كفالة-Sponsership
A21: 17 | B21: =_xlfn.XLOOKUP(Master_Employee[[#This Row],[Name_AR]],Lists!AN:AN,Lists!AL:AL," ",0) -> O207 | C21: =_xlfn.XLOOKUP(Master_Employee[[#This Row],[Department]],tbl_Dept[Dept_Name],tbl_Dept[Dept_ID],"",0) -> FIN_D02 | D21: التشطيبات | E21: =_xlfn.XLOOKUP(Master_Employee[[#This Row],[Dept_ID]],tbl_Dept[Dept_ID],tbl_Dept[Dept_Name_EN],"",0) -> Finishes | G21: =_xlfn.XLOOKUP(Master_Employee[[#This Row],[Supervisor_Name]],EmpNames,EmpIDs,"",0) | H21: محمد نور الأسلام | I21: =_xlfn.XLOOKUP(Master_Employee[[#This Row],[Emp_ID]],Lists!AL:AL,Lists!AO:AO,"",0) -> 0 | L21: =IF(Master_Employee[[#This Row],[Q_ID_Expire_Date]]="","",TODAY()-Master_Employee[[#This Row],[Q_ID_Expire_Date]]) | M21: نيبالي – Nepali | N21: عامل الثرى دى | R21: works - يعمل | S21: =_xlfn.XLOOKUP(Master_Employee[[#This Row],[Emp_Status]],Emp_Status[Emp_Status],Emp_Status[Status_Code],"",0) -> W_01 | T21: cash - نقدا | U21: =_xlfn.XLOOKUP(Master_Employee[[#This Row],[Payment_Method]],Pay[Payment_Method],Pay[Pay_Code],"",0) -> C_0 | Y21: 1700 | AA21: 300 | AB21: 200 | AC21: =Master_Employee[[#This Row],[Basic_Salary]]+Master_Employee[[#This Row],[Living_Allowance]]+Master_Employee[[#This Row],[Transport_Allowance]]+Master_Employee[[#This Row],[Other_Allowance]] -> 2200 | AD21: =(Master_Employee[[#This Row],[Total_Salary]]/30) -> 73.333333 | AE21: =Master_Employee[[#This Row],[Daily_Rate]]/8 -> 9.1666667 | AF21: =(Master_Employee[[#This Row],[Basic_Salary]]/30/8)*(Master_Employee[[#This Row],[OT_Multiplier]]) -> 7.0833333 | AG21: =1 -> 1 | AH21: Worker | AI21: كفالة-Sponsership
A22: 18 | B22: =_xlfn.XLOOKUP(Master_Employee[[#This Row],[Name_AR]],Lists!AN:AN,Lists!AL:AL," ",0) -> O163 | C22: =_xlfn.XLOOKUP(Master_Employee[[#This Row],[Department]],tbl_Dept[Dept_Name],tbl_Dept[Dept_ID],"",0) -> FIN_D02 | D22: التشطيبات | E22: =_xlfn.XLOOKUP(Master_Employee[[#This Row],[Dept_ID]],tbl_Dept[Dept_ID],tbl_Dept[Dept_Name_EN],"",0) -> Finishes | G22: =_xlfn.XLOOKUP(Master_Employee[[#This Row],[Supervisor_Name]],EmpNames,EmpIDs,"",0) | H22: عبد الباسي عبد الرحمن اشير | I22: =_xlfn.XLOOKUP(Master_Employee[[#This Row],[Emp_ID]],Lists!AL:AL,Lists!AO:AO,"",0) -> 0 | L22: =IF(Master_Employee[[#This Row],[Q_ID_Expire_Date]]="","",TODAY()-Master_Employee[[#This Row],[Q_ID_Expire_Date]]) | M22: نيبالي – Nepali | N22: عامل الثرى دى | R22: works - يعمل | S22: =_xlfn.XLOOKUP(Master_Employee[[#This Row],[Emp_Status]],Emp_Status[Emp_Status],Emp_Status[Status_Code],"",0) -> W_01 | T22: cash - نقدا | U22: =_xlfn.XLOOKUP(Master_Employee[[#This Row],[Payment_Method]],Pay[Payment_Method],Pay[Pay_Code],"",0) -> C_0 | Y22: 1500 | AA22: 300 | AB22: 500 | AC22: =Master_Employee[[#This Row],[Basic_Salary]]+Master_Employee[[#This Row],[Living_Allowance]]+Master_Employee[[#This Row],[Transport_Allowance]]+Master_Employee[[#This Row],[Other_Allowance]] -> 2300 | AD22: =(Master_Employee[[#This Row],[Total_Salary]]/30) -> 76.666667 | AE22: =Master_Employee[[#This Row],[Daily_Rate]]/8 -> 9.5833333 | AF22: =(Master_Employee[[#This Row],[Basic_Salary]]/30/8)*(Master_Employee[[#This Row],[OT_Multiplier]]) -> 6.25 | AG22: =1 -> 1 | AH22: Worker | AI22: كفالة-Sponsership
A23: 19 | B23: =_xlfn.XLOOKUP(Master_Employee[[#This Row],[Name_AR]],Lists!AN:AN,Lists!AL:AL," ",0) -> O48 | C23: =_xlfn.XLOOKUP(Master_Employee[[#This Row],[Department]],tbl_Dept[Dept_Name],tbl_Dept[Dept_ID],"",0) -> FIN_D02 | D23: التشطيبات | E23: =_xlfn.XLOOKUP(Master_Employee[[#This Row],[Dept_ID]],tbl_Dept[Dept_ID],tbl_Dept[Dept_Name_EN],"",0) -> Finishes | G23: =_xlfn.XLOOKUP(Master_Employee[[#This Row],[Supervisor_Name]],EmpNames,EmpIDs,"",0) | H23: بنود كومار ساه | I23: =_xlfn.XLOOKUP(Master_Employee[[#This Row],[Emp_ID]],Lists!AL:AL,Lists!AO:AO,"",0) -> 0 | L23: =IF(Master_Employee[[#This Row],[Q_ID_Expire_Date]]="","",TODAY()-Master_Employee[[#This Row],[Q_ID_Expire_Date]]) | M23: نيبالي – Nepali | N23: فني بلاستر | R23: works - يعمل | S23: =_xlfn.XLOOKUP(Master_Employee[[#This Row],[Emp_Status]],Emp_Status[Emp_Status],Emp_Status[Status_Code],"",0) -> W_01 | T23: cash - نقدا | U23: =_xlfn.XLOOKUP(Master_Employee[[#This Row],[Payment_Method]],Pay[Payment_Method],Pay[Pay_Code],"",0) -> C_0 | Y23: 1500 | AA23: 300 | AB23: 700 | AC23: =Master_Employee[[#This Row],[Basic_Salary]]+Master_Employee[[#This Row],[Living_Allowance]]+Master_Employee[[#This Row],[Transport_Allowance]]+Master_Employee[[#This Row],[Other_Allowance]] -> 2500 | AD23: =(Master_Employee[[#This Row],[Total_Salary]]/30) -> 83.333333 | AE23: =Master_Employee[[#This Row],[Daily_Rate]]/8 -> 10.416667 | AF23: =(Master_Employee[[#This Row],[Basic_Salary]]/30/8)*(Master_Employee[[#This Row],[OT_Multiplier]]) -> 6.25 | AG23: =1 -> 1 | AH23: Worker | AI23: كفالة-Sponsership
A24: 20 | B24: =_xlfn.XLOOKUP(Master_Employee[[#This Row],[Name_AR]],Lists!AN:AN,Lists!AL:AL," ",0) -> O187 | C24: =_xlfn.XLOOKUP(Master_Employee[[#This Row],[Department]],tbl_Dept[Dept_Name],tbl_Dept[Dept_ID],"",0) -> FIN_D02 | D24: التشطيبات | E24: =_xlfn.XLOOKUP(Master_Employee[[#This Row],[Dept_ID]],tbl_Dept[Dept_ID],tbl_Dept[Dept_Name_EN],"",0) -> Finishes | G24: =_xlfn.XLOOKUP(Master_Employee[[#This Row],[Supervisor_Name]],EmpNames,EmpIDs,"",0) | H24: مد موجمل حقي | I24: =_xlfn.XLOOKUP(Master_Employee[[#This Row],[Emp_ID]],Lists!AL:AL,Lists!AO:AO,"",0) -> 0 | L24: =IF(Master_Employee[[#This Row],[Q_ID_Expire_Date]]="","",TODAY()-Master_Employee[[#This Row],[Q_ID_Expire_Date]]) | M24: نيبالي – Nepali | N24: ناطور | R24: works - يعمل | S24: =_xlfn.XLOOKUP(Master_Employee[[#This Row],[Emp_Status]],Emp_Status[Emp_Status],Emp_Status[Status_Code],"",0) -> W_01 | T24: cash - نقدا | U24: =_xlfn.XLOOKUP(Master_Employee[[#This Row],[Payment_Method]],Pay[Payment_Method],Pay[Pay_Code],"",0) -> C_0 | Y24: 1000 | AA24: 300 | AB24: 200 | AC24: =Master_Employee[[#This Row],[Basic_Salary]]+Master_Employee[[#This Row],[Living_Allowance]]+Master_Employee[[#This Row],[Transport_Allowance]]+Master_Employee[[#This Row],[Other_Allowance]] -> 1500 | AD24: =(Master_Employee[[#This Row],[Total_Salary]]/30) -> 50 | AE24: =Master_Employee[[#This Row],[Daily_Rate]]/8 -> 6.25 | AF24: =(Master_Employee[[#This Row],[Basic_Salary]]/30/8)*(Master_Employee[[#This Row],[OT_Multiplier]]) -> 4.1666667 | AG24: =1 -> 1 | AH24: Worker | AI24: كفالة-Sponsership
A25: 21 | B25: =_xlfn.XLOOKUP(Master_Employee[[#This Row],[Name_AR]],Lists!AN:AN,Lists!AL:AL," ",0) -> 146 | C25: =_xlfn.XLOOKUP(Master_Employee[[#This Row],[Department]],tbl_Dept[Dept_Name],tbl_Dept[Dept_ID],"",0) -> ADM_D01 | D25: الإدارة | E25: =_xlfn.XLOOKUP(Master_Employee[[#This Row],[Dept_ID]],tbl_Dept[Dept_ID],tbl_Dept[Dept_Name_EN],"",0) -> Administration | G25: =_xlfn.XLOOKUP(Master_Employee[[#This Row],[Supervisor_Name]],EmpNames,EmpIDs,"",0) | H25: ﻣﺎﻣﻮﻥ ﺍﺣﻤﺪ ﺷﻮﻧﻮ ﻣﻴﺎﻩ | I25: =_xlfn.XLOOKUP(Master_Employee[[#This Row],[Emp_ID]],Lists!AL:AL,Lists!AO:AO,"",0) -> 0 | L25: =IF(Master_Employee[[#This Row],[Q_ID_Expire_Date]]="","",TODAY()-Master_Employee[[#This Row],[Q_ID_Expire_Date]]) | M25: فلبيني – Filipino | N25: عامل | R25: works - يعمل | S25: =_xlfn.XLOOKUP(Master_Employee[[#This Row],[Emp_Status]],Emp_Status[Emp_Status],Emp_Status[Status_Code],"",0) -> W_01 | T25: Vodafone - فودافون | U25: =_xlfn.XLOOKUP(Master_Employee[[#This Row],[Payment_Method]],Pay[Payment_Method],Pay[Pay_Code],"",0) -> V_0 | Y25: 1000 | AA25: 300 | AB25: 0 | AC25: =Master_Employee[[#This Row],[Basic_Salary]]+Master_Employee[[#This Row],[Living_Allowance]]+Master_Employee[[#This Row],[Transport_Allowance]]+Master_Employee[[#This Row],[Other_Allowance]] -> 1300 | AD25: =(Master_Employee[[#This Row],[Total_Salary]]/30) -> 43.333333 | AE25: =Master_Employee[[#This Row],[Daily_Rate]]/8 -> 5.4166667 | AF25: =(Master_Employee[[#This Row],[Basic_Salary]]/30/8)*(Master_Employee[[#This Row],[OT_Multiplier]]) -> 4.1666667 | AG25: =1 -> 1 | AH25: Worker | AI25: كفالة-Sponsership
A26: 22 | B26: =_xlfn.XLOOKUP(Master_Employee[[#This Row],[Name_AR]],Lists!AN:AN,Lists!AL:AL," ",0) -> O304 | C26: =_xlfn.XLOOKUP(Master_Employee[[#This Row],[Department]],tbl_Dept[Dept_Name],tbl_Dept[Dept_ID],"",0) -> ADM_D01 | D26: الإدارة | E26: =_xlfn.XLOOKUP(Master_Employee[[#This Row],[Dept_ID]],tbl_Dept[Dept_ID],tbl_Dept[Dept_Name_EN],"",0) -> Administration | G26: =_xlfn.XLOOKUP(Master_Employee[[#This Row],[Supervisor_Name]],EmpNames,EmpIDs,"",0) | H26: صلاح عبدالرحمن الحاج احمد | I26: =_xlfn.XLOOKUP(Master_Employee[[#This Row],[Emp_ID]],Lists!AL:AL,Lists!AO:AO,"",0) -> 0 | L26: =IF(Master_Employee[[#This Row],[Q_ID_Expire_Date]]="","",TODAY()-Master_Employee[[#This Row],[Q_ID_Expire_Date]]) | M26: فلبيني – Filipino | N26: فورمان | R26: works - يعمل | S26: =_xlfn.XLOOKUP(Master_Employee[[#This Row],[Emp_Status]],Emp_Status[Emp_Status],Emp_Status[Status_Code],"",0) -> W_01 | T26: Bank - بنك | U26: =_xlfn.XLOOKUP(Master_Employee[[#This Row],[Payment_Method]],Pay[Payment_Method],Pay[Pay_Code],"",0) -> B_0 | Y26: 1000 | AA26: 300 | AB26: 500 | AC26: =Master_Employee[[#This Row],[Basic_Salary]]+Master_Employee[[#This Row],[Living_Allowance]]+Master_Employee[[#This Row],[Transport_Allowance]]+Master_Employee[[#This Row],[Other_Allowance]] -> 1800 | AD26: =(Master_Employee[[#This Row],[Total_Salary]]/30) -> 60 | AE26: =Master_Employee[[#This Row],[Daily_Rate]]/8 -> 7.5 | AF26: =(Master_Employee[[#This Row],[Basic_Salary]]/30/8)*(Master_Employee[[#This Row],[OT_Multiplier]]) -> 4.1666667 | AG26: =1 -> 1 | AH26: Worker | AI26: كفالة-Sponsership
... A30: 26 | B30: =_xlfn.XLOOKUP(Master_Employee[[#This Row],[Name_AR]],Lists!AN:AN,Lists!AL:AL," ",0) -> 314 | C30: =_xlfn.XLOOKUP(Master_Employee[[#This Row],[Department]],tbl_Dept[Dept_Name],tbl_Dept[Dept_ID],"",0) -> ADM_D01 | D30: الإدارة | E30: =_xlfn.XLOOKUP(Master_Employee[[#This Row],[Dept_ID]],tbl_Dept[Dept_ID],tbl_Dept[Dept_Name_EN],"",0) -> Administration | G30: =_xlfn.XLOOKUP(Master_Employee[[#This Row],[Supervisor_Name]],EmpNames,EmpIDs,"",0) | H30: محمد عرلاان | I30: =_xlfn.XLOOKUP(Master_Employee[[#This Row],[Emp_ID]],Lists!AL:AL,Lists!AO:AO,"",0) -> 0 | L30: =IF(Master_Employee[[#This Row],[Q_ID_Expire_Date]]="","",TODAY()-Master_Employee[[#This Row],[Q_ID_Expire_Date]]) | M30: إندونيسي – Indonesian | N30: فنى | R30: New appointment - تعيين جديد | S30: =_xlfn.XLOOKUP(Master_Employee[[#This Row],[Emp_Status]],Emp_Status[Emp_Status],Emp_Status[Status_Code],"",0) -> N_01 | T30: Bank - بنك | U30: =_xlfn.XLOOKUP(Master_Employee[[#This Row],[Payment_Method]],Pay[Payment_Method],Pay[Pay_Code],"",0) -> B_0 | Y30: 1500 | AA30: 300 | AB30: 700 | AC30: =Master_Employee[[#This Row],[Basic_Salary]]+Master_Employee[[#This Row],[Living_Allowance]]+Master_Employee[[#This Row],[Transport_Allowance]]+Master_Employee[[#This Row],[Other_Allowance]] -> 2500 | AD30: =(Master_Employee[[#This Row],[Total_Salary]]/30) -> 83.333333 | AE30: =Master_Employee[[#This Row],[Daily_Rate]]/8 -> 10.416667 | AF30: =(Master_Employee[[#This Row],[Basic_Salary]]/30/8)*(Master_Employee[[#This Row],[OT_Multiplier]]) -> 6.25 | AG30: =1 -> 1 | AH30: Worker | AI30: كفالة-Sponsership

Sheet Transactions
A1: 💳 Transactions – الحركات المالية (سلف / خصم / بونص)
A2: م | B2: رقم المعاملة | C2: كود الموظف | D2: اسم الموظف بالعربي | E2: اسم الموظف بالانجليزي | F2: القسم | G2: المشروع | H2: التاريخ | I2: النوع | K2: السبب | L2: المبلغ | M2: ملاحظات
A3: # | B3: Trans_ID | C3: Emp_ID | D3: Name_AR | E3: Name_EN | F3: Department | G3: Project_Name | H3: Date | I3: Type | J3: Type_Code | K3: Reasons | L3: Amount | M3: Notes
A4: 1 | B4: TRN-001 | C4: O60 | D4: =IFERROR(_xlfn.XLOOKUP(C4,Master_Employee[Emp_ID],Master_Employee[Name_AR],"",0),"") -> محمد اكبر صافي | E4: =IFERROR(_xlfn.XLOOKUP(C4,Master_Employee[Emp_ID],Master_Employee[Name_EN],"",0),"") -> Muhammad Akbar Safi | F4: =IFERROR(_xlfn.XLOOKUP(C4,Master_Employee[Emp_ID],Master_Employee[Department],"",0),"") -> الإنشاءات | H4: 46082 | I4: بونص - Bonus | J4: =_xlfn.XLOOKUP(tbl_Transactions[[#This Row],[Type]],Type[Trans_Type],Type[Type_Code],"",0) -> Bo_01 | L4: 100 | P4: في حالة السلفة (LO_01) يجب إدخال سبب قبل كتابة المبلغ
A5: 2 | B5: TRN-002 | C5: O61 | D5: =IFERROR(_xlfn.XLOOKUP(C5,Master_Employee[Emp_ID],Master_Employee[Name_AR],"",0),"") -> عبدالحكيم رستم انصاري | E5: =IFERROR(_xlfn.XLOOKUP(C5,Master_Employee[Emp_ID],Master_Employee[Name_EN],"",0),"") -> Abdul Hakim Rustam Ansari | F5: =IFERROR(_xlfn.XLOOKUP(C5,Master_Employee[Emp_ID],Master_Employee[Department],"",0),"") -> الإنشاءات | H5: 46083 | I5: خصم - Deduction | J5: =_xlfn.XLOOKUP(tbl_Transactions[[#This Row],[Type]],Type[Trans_Type],Type[Type_Code],"",0) -> De_01 | L5: 50 | P5: مينفعش ادخل أي داتا في صفوف البلانك
A6: 4 | B6: TRN-004 | C6: O175 | D6: =IFERROR(_xlfn.XLOOKUP(C6,Master_Employee[Emp_ID],Master_Employee[Name_AR],"",0),"") -> انوار انصاري رحيم انصاري | E6: =IFERROR(_xlfn.XLOOKUP(C6,Master_Employee[Emp_ID],Master_Employee[Name_EN],"",0),"") -> Anwar Ansari Rahim Ansari | F6: =IFERROR(_xlfn.XLOOKUP(C6,Master_Employee[Emp_ID],Master_Employee[Department],"",0),"") -> الإنشاءات | H6: 46085 | I6: سلف - Loans | J6: =_xlfn.XLOOKUP(tbl_Transactions[[#This Row],[Type]],Type[Trans_Type],Type[Type_Code],"",0) -> Lo_01 | L6: 500 | O6: كل الموظفين في كل الأقسام بحالتهم التلاته
A7: =IFERROR(IF(C7="","",ROW()-2),"") -> 5 | B7: TRN-005 | C7: O229 | D7: =IFERROR(_xlfn.XLOOKUP(C7,Master_Employee[Emp_ID],Master_Employee[Name_AR],"",0),"") -> محمد سهيل محمد سليم | E7: =IFERROR(_xlfn.XLOOKUP(C7,Master_Employee[Emp_ID],Master_Employee[Name_EN],"",0),"") -> Mohammed Suhail Mohammed Salim | F7: =IFERROR(_xlfn.XLOOKUP(C7,Master_Employee[Emp_ID],Master_Employee[Department],"",0),"") -> الإنشاءات | H7: 46082 | I7: سلف - Loans | J7: =_xlfn.XLOOKUP(tbl_Transactions[[#This Row],[Type]],Type[Trans_Type],Type[Type_Code],"",0) -> Lo_01 | L7: 100 | O7: {=_xlfn._xlws.FILTER( Master_Employee[Emp_ID], ISNUMBER(MATCH(Master_Employee[Status_Code],Valid_Status[],0)), "لا يوجد عمال" )} -> O60 | P7: =OR( J4<>"Lo_01", AND(J4="Lo_01",K4<>""), L4="" ) -> TRUE
A8: =IFERROR(IF(C8="","",ROW()-2),"") -> 6 | B8: TRN-006 | C8: 146 | D8: =IFERROR(_xlfn.XLOOKUP(C8,Master_Employee[Emp_ID],Master_Employee[Name_AR],"",0),"") -> ﻣﺎﻣﻮﻥ ﺍﺣﻤﺪ ﺷﻮﻧﻮ ﻣﻴﺎﻩ | E8: =IFERROR(_xlfn.XLOOKUP(C8,Master_Employee[Emp_ID],Master_Employee[Name_EN],"",0),"") -> 0 | F8: =IFERROR(_xlfn.XLOOKUP(C8,Master_Employee[Emp_ID],Master_Employee[Department],"",0),"") -> الإدارة | H8: 46091 | I8: خصم - Deduction | J8: =_xlfn.XLOOKUP(tbl_Transactions[[#This Row],[Type]],Type[Trans_Type],Type[Type_Code],"",0) -> De_01 | L8: 200 | O8: O61
A9: =IFERROR(IF(C9="","",ROW()-2),"") | B9: TRN-007 | D9: =IFERROR(_xlfn.XLOOKUP(C9,Master_Employee[Emp_ID],Master_Employee[Name_AR],"",0),"") | E9: =IFERROR(_xlfn.XLOOKUP(C9,Master_Employee[Emp_ID],Master_Employee[Name_EN],"",0),"") | F9: =IFERROR(_xlfn.XLOOKUP(C9,Master_Employee[Emp_ID],Master_Employee[Department],"",0),"") | J9: =_xlfn.XLOOKUP(tbl_Transactions[[#This Row],[Type]],Type[Trans_Type],Type[Type_Code],"",0) | O9: O175
A10: =IFERROR(IF(C10="","",ROW()-2),"") | B10: TRN-008 | D10: =IFERROR(_xlfn.XLOOKUP(C10,Master_Employee[Emp_ID],Master_Employee[Name_AR],"",0),"") | E10: =IFERROR(_xlfn.XLOOKUP(C10,Master_Employee[Emp_ID],Master_Employee[Name_EN],"",0),"") | F10: =IFERROR(_xlfn.XLOOKUP(C10,Master_Employee[Emp_ID],Master_Employee[Department],"",0),"") | J10: =_xlfn.XLOOKUP(tbl_Transactions[[#This Row],[Type]],Type[Trans_Type],Type[Type_Code],"",0) | O10: O180
A11: =IFERROR(IF(C11="","",ROW()-2),"") | B11: TRN-009 | D11: =IFERROR(_xlfn.XLOOKUP(C11,Master_Employee[Emp_ID],Master_Employee[Name_AR],"",0),"") | E11: =IFERROR(_xlfn.XLOOKUP(C11,Master_Employee[Emp_ID],Master_Employee[Name_EN],"",0),"") | F11: =IFERROR(_xlfn.XLOOKUP(C11,Master_Employee[Emp_ID],Master_Employee[Department],"",0),"") | J11: =_xlfn.XLOOKUP(tbl_Transactions[[#This Row],[Type]],Type[Trans_Type],Type[Type_Code],"",0) | O11: O201
A12: =IFERROR(IF(C12="","",ROW()-2),"") | B12: TRN-010 | D12: =IFERROR(_xlfn.XLOOKUP(C12,Master_Employee[Emp_ID],Master_Employee[Name_AR],"",0),"") | E12: =IFERROR(_xlfn.XLOOKUP(C12,Master_Employee[Emp_ID],Master_Employee[Name_EN],"",0),"") | F12: =IFERROR(_xlfn.XLOOKUP(C12,Master_Employee[Emp_ID],Master_Employee[Department],"",0),"") | J12: =_xlfn.XLOOKUP(tbl_Transactions[[#This Row],[Type]],Type[Trans_Type],Type[Type_Code],"",0) | O12: O229
A13: =IFERROR(IF(C13="","",ROW()-2),"") | B13: TRN-011 | D13: =IFERROR(_xlfn.XLOOKUP(C13,Master_Employee[Emp_ID],Master_Employee[Name_AR],"",0),"") | E13: =IFERROR(_xlfn.XLOOKUP(C13,Master_Employee[Emp_ID],Master_Employee[Name_EN],"",0),"") | F13: =IFERROR(_xlfn.XLOOKUP(C13,Master_Employee[Emp_ID],Master_Employee[Department],"",0),"") | J13: =_xlfn.XLOOKUP(tbl_Transactions[[#This Row],[Type]],Type[Trans_Type],Type[Type_Code],"",0) | O13: 244
A14: =IFERROR(IF(C14="","",ROW()-2),"") | B14: TRN-012 | D14: =IFERROR(_xlfn.XLOOKUP(C14,Master_Employee[Emp_ID],Master_Employee[Name_AR],"",0),"") | E14: =IFERROR(_xlfn.XLOOKUP(C14,Master_Employee[Emp_ID],Master_Employee[Name_EN],"",0),"") | F14: =IFERROR(_xlfn.XLOOKUP(C14,Master_Employee[Emp_ID],Master_Employee[Department],"",0),"") | J14: =_xlfn.XLOOKUP(tbl_Transactions[[#This Row],[Type]],Type[Trans_Type],Type[Type_Code],"",0) | O14: 243
A15: =IFERROR(IF(C15="","",ROW()-2),"") | B15: TRN-013 | D15: =IFERROR(_xlfn.XLOOKUP(C15,Master_Employee[Emp_ID],Master_Employee[Name_AR],"",0),"") | E15: =IFERROR(_xlfn.XLOOKUP(C15,Master_Employee[Emp_ID],Master_Employee[Name_EN],"",0),"") | F15: =IFERROR(_xlfn.XLOOKUP(C15,Master_Employee[Emp_ID],Master_Employee[Department],"",0),"") | J15: =_xlfn.XLOOKUP(tbl_Transactions[[#This Row],[Type]],Type[Trans_Type],Type[Type_Code],"",0) | O15: 389
A16: =IFERROR(IF(C16="","",ROW()-2),"") | D16: =IFERROR(_xlfn.XLOOKUP(C16,Master_Employee[Emp_ID],Master_Employee[Name_AR],"",0),"") | E16: =IFERROR(_xlfn.XLOOKUP(C16,Master_Employee[Emp_ID],Master_Employee[Name_EN],"",0),"") | F16: =IFERROR(_xlfn.XLOOKUP(C16,Master_Employee[Emp_ID],Master_Employee[Department],"",0),"") | J16: =_xlfn.XLOOKUP(tbl_Transactions[[#This Row],[Type]],Type[Trans_Type],Type[Type_Code],"",0) | O16: 411
A17: =IFERROR(IF(C17="","",ROW()-2),"") | D17: =IFERROR(_xlfn.XLOOKUP(C17,Master_Employee[Emp_ID],Master_Employee[Name_AR],"",0),"") | E17: =IFERROR(_xlfn.XLOOKUP(C17,Master_Employee[Emp_ID],Master_Employee[Name_EN],"",0),"") | F17: =IFERROR(_xlfn.XLOOKUP(C17,Master_Employee[Emp_ID],Master_Employee[Department],"",0),"") | J17: =_xlfn.XLOOKUP(tbl_Transactions[[#This Row],[Type]],Type[Trans_Type],Type[Type_Code],"",0) | O17: 448
A18: =IFERROR(IF(C18="","",ROW()-2),"") | D18: =IFERROR(_xlfn.XLOOKUP(C18,Master_Employee[Emp_ID],Master_Employee[Name_AR],"",0),"") | E18: =IFERROR(_xlfn.XLOOKUP(C18,Master_Employee[Emp_ID],Master_Employee[Name_EN],"",0),"") | F18: =IFERROR(_xlfn.XLOOKUP(C18,Master_Employee[Emp_ID],Master_Employee[Department],"",0),"") | J18: =_xlfn.XLOOKUP(tbl_Transactions[[#This Row],[Type]],Type[Trans_Type],Type[Type_Code],"",0) | O18: 247
A19: =IFERROR(IF(C19="","",ROW()-2),"") | D19: =IFERROR(_xlfn.XLOOKUP(C19,Master_Employee[Emp_ID],Master_Employee[Name_AR],"",0),"") | E19: =IFERROR(_xlfn.XLOOKUP(C19,Master_Employee[Emp_ID],Master_Employee[Name_EN],"",0),"") | F19: =IFERROR(_xlfn.XLOOKUP(C19,Master_Employee[Emp_ID],Master_Employee[Department],"",0),"") | J19: =_xlfn.XLOOKUP(tbl_Transactions[[#This Row],[Type]],Type[Trans_Type],Type[Type_Code],"",0) | O19: O204
A20: =IFERROR(IF(C20="","",ROW()-2),"") | D20: =IFERROR(_xlfn.XLOOKUP(C20,Master_Employee[Emp_ID],Master_Employee[Name_AR],"",0),"") | E20: =IFERROR(_xlfn.XLOOKUP(C20,Master_Employee[Emp_ID],Master_Employee[Name_EN],"",0),"") | F20: =IFERROR(_xlfn.XLOOKUP(C20,Master_Employee[Emp_ID],Master_Employee[Department],"",0),"") | J20: =_xlfn.XLOOKUP(tbl_Transactions[[#This Row],[Type]],Type[Trans_Type],Type[Type_Code],"",0) | O20: O207
A21: =IFERROR(IF(C21="","",ROW()-2),"") | D21: =IFERROR(_xlfn.XLOOKUP(C21,Master_Employee[Emp_ID],Master_Employee[Name_AR],"",0),"") | E21: =IFERROR(_xlfn.XLOOKUP(C21,Master_Employee[Emp_ID],Master_Employee[Name_EN],"",0),"") | F21: =IFERROR(_xlfn.XLOOKUP(C21,Master_Employee[Emp_ID],Master_Employee[Department],"",0),"") | J21: =_xlfn.XLOOKUP(tbl_Transactions[[#This Row],[Type]],Type[Trans_Type],Type[Type_Code],"",0) | O21: O163
A22: =IFERROR(IF(C22="","",ROW()-2),"") | D22: =IFERROR(_xlfn.XLOOKUP(C22,Master_Employee[Emp_ID],Master_Employee[Name_AR],"",0),"") | E22: =IFERROR(_xlfn.XLOOKUP(C22,Master_Employee[Emp_ID],Master_Employee[Name_EN],"",0),"") | F22: =IFERROR(_xlfn.XLOOKUP(C22,Master_Employee[Emp_ID],Master_Employee[Department],"",0),"") | J22: =_xlfn.XLOOKUP(tbl_Transactions[[#This Row],[Type]],Type[Trans_Type],Type[Type_Code],"",0) | O22: O48
A23: =IFERROR(IF(C23="","",ROW()-2),"") | D23: =IFERROR(_xlfn.XLOOKUP(C23,Master_Employee[Emp_ID],Master_Employee[Name_AR],"",0),"") | E23: =IFERROR(_xlfn.XLOOKUP(C23,Master_Employee[Emp_ID],Master_Employee[Name_EN],"",0),"") | F23: =IFERROR(_xlfn.XLOOKUP(C23,Master_Employee[Emp_ID],Master_Employee[Department],"",0),"") | J23: =_xlfn.XLOOKUP(tbl_Transactions[[#This Row],[Type]],Type[Trans_Type],Type[Type_Code],"",0) | O23: O187
